2025-05-06 08:27:59,278 - uvicorn.error - INFO - Shutting down
2025-05-06 08:27:59,380 - uvicorn.error - INFO - Waiting for application shutdown.
2025-05-06 08:27:59,380 - uvicorn.error - INFO - Application shutdown complete.
2025-05-06 08:27:59,380 - uvicorn.error - INFO - Finished server process [9]
2025-05-06 08:27:59,450 - uvicorn.error - INFO - Stopping reloader process [1]
2025-05-06 08:28:09,981 - uvicorn.error - INFO - Will watch for changes in these directories: ['/app']
2025-05-06 08:28:09,981 - uvicorn.error - INFO - Uvicorn running on https://0.0.0.0:8000 (Press CTRL+C to quit)
2025-05-06 08:28:09,981 - uvicorn.error - INFO - Started reloader process [1] using statreload
2025-05-06 08:28:10,384 - uvicorn.error - INFO - Started server process [9]
2025-05-06 08:28:10,384 - uvicorn.error - INFO - Waiting for application startup.
2025-05-06 08:28:10,406 - main - INFO - Инициализация тестовых пользователей
2025-05-06 08:28:10,407 - main - INFO - Создан тестовый пользователь: grigory
2025-05-06 08:28:10,407 - main - INFO - Создан тестовый пользователь: user1
2025-05-06 08:28:10,408 - main - INFO - Создан тестовый пользователь: user2
2025-05-06 08:28:10,408 - main - INFO - Инициализация завершена
2025-05-06 08:28:10,408 - uvicorn.error - INFO - Application startup complete.
2025-05-06 08:28:29,478 - main - INFO - Попытка входа пользователя: grigory
2025-05-06 08:28:29,479 - main - WARNING - Неудачная попытка входа: неверный пароль для пользователя grigory
2025-05-06 08:28:39,024 - main - INFO - Попытка входа пользователя: grigory
2025-05-06 08:28:39,028 - main - INFO - Успешный вход пользователя: grigory
2025-05-06 08:28:39,129 - main - INFO - Успешная аутентификация пользователя: grigory
2025-05-06 08:28:39,130 - main - INFO - Запрос профиля пользователя: grigory
2025-05-06 08:28:44,329 - main - INFO - Успешная аутентификация пользователя: grigory
2025-05-06 08:28:44,332 - uvicorn.error - ERROR - Exception in ASGI application
Traceback (most recent call last):
  File "/usr/local/lib/python3.9/site-packages/uvicorn/protocols/http/h11_impl.py", line 373, in run_asgi
    result = await app(self.scope, self.receive, self.send)
  File "/usr/local/lib/python3.9/site-packages/uvicorn/middleware/proxy_headers.py", line 75, in __call__
    return await self.app(scope, receive, send)
  File "/usr/local/lib/python3.9/site-packages/fastapi/applications.py", line 1054, in __call__
    await super().__call__(scope, receive, send)
  File "/usr/local/lib/python3.9/site-packages/starlette/applications.py", line 112, in __call__
    await self.middleware_stack(scope, receive, send)
  File "/usr/local/lib/python3.9/site-packages/starlette/middleware/errors.py", line 187, in __call__
    raise exc
  File "/usr/local/lib/python3.9/site-packages/starlette/middleware/errors.py", line 165, in __call__
    await self.app(scope, receive, _send)
  File "/usr/local/lib/python3.9/site-packages/starlette/middleware/cors.py", line 85, in __call__
    await self.app(scope, receive, send)
  File "/usr/local/lib/python3.9/site-packages/starlette/middleware/exceptions.py", line 62, in __call__
    await wrap_app_handling_exceptions(self.app, conn)(scope, receive, send)
  File "/usr/local/lib/python3.9/site-packages/starlette/_exception_handler.py", line 53, in wrapped_app
    raise exc
  File "/usr/local/lib/python3.9/site-packages/starlette/_exception_handler.py", line 42, in wrapped_app
    await app(scope, receive, sender)
  File "/usr/local/lib/python3.9/site-packages/starlette/routing.py", line 714, in __call__
    await self.middleware_stack(scope, receive, send)
  File "/usr/local/lib/python3.9/site-packages/starlette/routing.py", line 734, in app
    await route.handle(scope, receive, send)
  File "/usr/local/lib/python3.9/site-packages/starlette/routing.py", line 288, in handle
    await self.app(scope, receive, send)
  File "/usr/local/lib/python3.9/site-packages/starlette/routing.py", line 76, in app
    await wrap_app_handling_exceptions(app, request)(scope, receive, send)
  File "/usr/local/lib/python3.9/site-packages/starlette/_exception_handler.py", line 53, in wrapped_app
    raise exc
  File "/usr/local/lib/python3.9/site-packages/starlette/_exception_handler.py", line 42, in wrapped_app
    await app(scope, receive, sender)
  File "/usr/local/lib/python3.9/site-packages/starlette/routing.py", line 73, in app
    response = await f(request)
  File "/usr/local/lib/python3.9/site-packages/fastapi/routing.py", line 301, in app
    raw_response = await run_endpoint_function(
  File "/usr/local/lib/python3.9/site-packages/fastapi/routing.py", line 212, in run_endpoint_function
    return await dependant.call(**values)
  File "/app/main.py", line 214, in get_questions
    result = await session.execute(
  File "/usr/local/lib/python3.9/site-packages/sqlalchemy/ext/asyncio/session.py", line 463, in execute
    result = await greenlet_spawn(
  File "/usr/local/lib/python3.9/site-packages/sqlalchemy/util/_concurrency_py3k.py", line 190, in greenlet_spawn
    result = context.switch(*args, **kwargs)
  File "/usr/local/lib/python3.9/site-packages/sqlalchemy/orm/session.py", line 2365, in execute
    return self._execute_internal(
  File "/usr/local/lib/python3.9/site-packages/sqlalchemy/orm/session.py", line 2149, in _execute_internal
    statement = coercions.expect(roles.StatementRole, statement)
  File "/usr/local/lib/python3.9/site-packages/sqlalchemy/sql/coercions.py", line 395, in expect
    resolved = impl._literal_coercion(
  File "/usr/local/lib/python3.9/site-packages/sqlalchemy/sql/coercions.py", line 621, in _literal_coercion
    return self._text_coercion(element, argname, **kw)
  File "/usr/local/lib/python3.9/site-packages/sqlalchemy/sql/coercions.py", line 614, in _text_coercion
    return _no_text_coercion(element, argname)
  File "/usr/local/lib/python3.9/site-packages/sqlalchemy/sql/coercions.py", line 584, in _no_text_coercion
    raise exc_cls(
sqlalchemy.exc.ArgumentError: Textual SQL expression 'SELECT q.id, q.question_t...' should be explicitly declared as text('SELECT q.id, q.question_t...')
2025-05-06 08:29:03,571 - main - INFO - Успешная аутентификация пользователя: grigory
2025-05-06 08:29:03,571 - uvicorn.error - ERROR - Exception in ASGI application
Traceback (most recent call last):
  File "/usr/local/lib/python3.9/site-packages/uvicorn/protocols/http/h11_impl.py", line 373, in run_asgi
    result = await app(self.scope, self.receive, self.send)
  File "/usr/local/lib/python3.9/site-packages/uvicorn/middleware/proxy_headers.py", line 75, in __call__
    return await self.app(scope, receive, send)
  File "/usr/local/lib/python3.9/site-packages/fastapi/applications.py", line 1054, in __call__
    await super().__call__(scope, receive, send)
  File "/usr/local/lib/python3.9/site-packages/starlette/applications.py", line 112, in __call__
    await self.middleware_stack(scope, receive, send)
  File "/usr/local/lib/python3.9/site-packages/starlette/middleware/errors.py", line 187, in __call__
    raise exc
  File "/usr/local/lib/python3.9/site-packages/starlette/middleware/errors.py", line 165, in __call__
    await self.app(scope, receive, _send)
  File "/usr/local/lib/python3.9/site-packages/starlette/middleware/cors.py", line 85, in __call__
    await self.app(scope, receive, send)
  File "/usr/local/lib/python3.9/site-packages/starlette/middleware/exceptions.py", line 62, in __call__
    await wrap_app_handling_exceptions(self.app, conn)(scope, receive, send)
  File "/usr/local/lib/python3.9/site-packages/starlette/_exception_handler.py", line 53, in wrapped_app
    raise exc
  File "/usr/local/lib/python3.9/site-packages/starlette/_exception_handler.py", line 42, in wrapped_app
    await app(scope, receive, sender)
  File "/usr/local/lib/python3.9/site-packages/starlette/routing.py", line 714, in __call__
    await self.middleware_stack(scope, receive, send)
  File "/usr/local/lib/python3.9/site-packages/starlette/routing.py", line 734, in app
    await route.handle(scope, receive, send)
  File "/usr/local/lib/python3.9/site-packages/starlette/routing.py", line 288, in handle
    await self.app(scope, receive, send)
  File "/usr/local/lib/python3.9/site-packages/starlette/routing.py", line 76, in app
    await wrap_app_handling_exceptions(app, request)(scope, receive, send)
  File "/usr/local/lib/python3.9/site-packages/starlette/_exception_handler.py", line 53, in wrapped_app
    raise exc
  File "/usr/local/lib/python3.9/site-packages/starlette/_exception_handler.py", line 42, in wrapped_app
    await app(scope, receive, sender)
  File "/usr/local/lib/python3.9/site-packages/starlette/routing.py", line 73, in app
    response = await f(request)
  File "/usr/local/lib/python3.9/site-packages/fastapi/routing.py", line 301, in app
    raw_response = await run_endpoint_function(
  File "/usr/local/lib/python3.9/site-packages/fastapi/routing.py", line 212, in run_endpoint_function
    return await dependant.call(**values)
  File "/app/main.py", line 214, in get_questions
    result = await session.execute(
  File "/usr/local/lib/python3.9/site-packages/sqlalchemy/ext/asyncio/session.py", line 463, in execute
    result = await greenlet_spawn(
  File "/usr/local/lib/python3.9/site-packages/sqlalchemy/util/_concurrency_py3k.py", line 190, in greenlet_spawn
    result = context.switch(*args, **kwargs)
  File "/usr/local/lib/python3.9/site-packages/sqlalchemy/orm/session.py", line 2365, in execute
    return self._execute_internal(
  File "/usr/local/lib/python3.9/site-packages/sqlalchemy/orm/session.py", line 2149, in _execute_internal
    statement = coercions.expect(roles.StatementRole, statement)
  File "/usr/local/lib/python3.9/site-packages/sqlalchemy/sql/coercions.py", line 395, in expect
    resolved = impl._literal_coercion(
  File "/usr/local/lib/python3.9/site-packages/sqlalchemy/sql/coercions.py", line 621, in _literal_coercion
    return self._text_coercion(element, argname, **kw)
  File "/usr/local/lib/python3.9/site-packages/sqlalchemy/sql/coercions.py", line 614, in _text_coercion
    return _no_text_coercion(element, argname)
  File "/usr/local/lib/python3.9/site-packages/sqlalchemy/sql/coercions.py", line 584, in _no_text_coercion
    raise exc_cls(
sqlalchemy.exc.ArgumentError: Textual SQL expression 'SELECT q.id, q.question_t...' should be explicitly declared as text('SELECT q.id, q.question_t...')
2025-05-06 08:29:07,708 - main - INFO - Успешная аутентификация пользователя: grigory
2025-05-06 08:29:07,708 - main - INFO - Запрос профиля пользователя: grigory
2025-05-06 08:29:08,774 - main - INFO - Успешная аутентификация пользователя: grigory
2025-05-06 08:29:08,776 - uvicorn.error - ERROR - Exception in ASGI application
Traceback (most recent call last):
  File "/usr/local/lib/python3.9/site-packages/uvicorn/protocols/http/h11_impl.py", line 373, in run_asgi
    result = await app(self.scope, self.receive, self.send)
  File "/usr/local/lib/python3.9/site-packages/uvicorn/middleware/proxy_headers.py", line 75, in __call__
    return await self.app(scope, receive, send)
  File "/usr/local/lib/python3.9/site-packages/fastapi/applications.py", line 1054, in __call__
    await super().__call__(scope, receive, send)
  File "/usr/local/lib/python3.9/site-packages/starlette/applications.py", line 112, in __call__
    await self.middleware_stack(scope, receive, send)
  File "/usr/local/lib/python3.9/site-packages/starlette/middleware/errors.py", line 187, in __call__
    raise exc
  File "/usr/local/lib/python3.9/site-packages/starlette/middleware/errors.py", line 165, in __call__
    await self.app(scope, receive, _send)
  File "/usr/local/lib/python3.9/site-packages/starlette/middleware/cors.py", line 85, in __call__
    await self.app(scope, receive, send)
  File "/usr/local/lib/python3.9/site-packages/starlette/middleware/exceptions.py", line 62, in __call__
    await wrap_app_handling_exceptions(self.app, conn)(scope, receive, send)
  File "/usr/local/lib/python3.9/site-packages/starlette/_exception_handler.py", line 53, in wrapped_app
    raise exc
  File "/usr/local/lib/python3.9/site-packages/starlette/_exception_handler.py", line 42, in wrapped_app
    await app(scope, receive, sender)
  File "/usr/local/lib/python3.9/site-packages/starlette/routing.py", line 714, in __call__
    await self.middleware_stack(scope, receive, send)
  File "/usr/local/lib/python3.9/site-packages/starlette/routing.py", line 734, in app
    await route.handle(scope, receive, send)
  File "/usr/local/lib/python3.9/site-packages/starlette/routing.py", line 288, in handle
    await self.app(scope, receive, send)
  File "/usr/local/lib/python3.9/site-packages/starlette/routing.py", line 76, in app
    await wrap_app_handling_exceptions(app, request)(scope, receive, send)
  File "/usr/local/lib/python3.9/site-packages/starlette/_exception_handler.py", line 53, in wrapped_app
    raise exc
  File "/usr/local/lib/python3.9/site-packages/starlette/_exception_handler.py", line 42, in wrapped_app
    await app(scope, receive, sender)
  File "/usr/local/lib/python3.9/site-packages/starlette/routing.py", line 73, in app
    response = await f(request)
  File "/usr/local/lib/python3.9/site-packages/fastapi/routing.py", line 301, in app
    raw_response = await run_endpoint_function(
  File "/usr/local/lib/python3.9/site-packages/fastapi/routing.py", line 212, in run_endpoint_function
    return await dependant.call(**values)
  File "/app/main.py", line 214, in get_questions
    result = await session.execute(
  File "/usr/local/lib/python3.9/site-packages/sqlalchemy/ext/asyncio/session.py", line 463, in execute
    result = await greenlet_spawn(
  File "/usr/local/lib/python3.9/site-packages/sqlalchemy/util/_concurrency_py3k.py", line 190, in greenlet_spawn
    result = context.switch(*args, **kwargs)
  File "/usr/local/lib/python3.9/site-packages/sqlalchemy/orm/session.py", line 2365, in execute
    return self._execute_internal(
  File "/usr/local/lib/python3.9/site-packages/sqlalchemy/orm/session.py", line 2149, in _execute_internal
    statement = coercions.expect(roles.StatementRole, statement)
  File "/usr/local/lib/python3.9/site-packages/sqlalchemy/sql/coercions.py", line 395, in expect
    resolved = impl._literal_coercion(
  File "/usr/local/lib/python3.9/site-packages/sqlalchemy/sql/coercions.py", line 621, in _literal_coercion
    return self._text_coercion(element, argname, **kw)
  File "/usr/local/lib/python3.9/site-packages/sqlalchemy/sql/coercions.py", line 614, in _text_coercion
    return _no_text_coercion(element, argname)
  File "/usr/local/lib/python3.9/site-packages/sqlalchemy/sql/coercions.py", line 584, in _no_text_coercion
    raise exc_cls(
sqlalchemy.exc.ArgumentError: Textual SQL expression 'SELECT q.id, q.question_t...' should be explicitly declared as text('SELECT q.id, q.question_t...')
2025-05-06 08:29:22,912 - main - INFO - Успешная аутентификация пользователя: grigory
2025-05-06 08:29:22,913 - main - INFO - Запрос профиля пользователя: grigory
2025-05-06 08:29:26,786 - main - INFO - Успешная аутентификация пользователя: grigory
2025-05-06 08:29:26,788 - uvicorn.error - ERROR - Exception in ASGI application
Traceback (most recent call last):
  File "/usr/local/lib/python3.9/site-packages/uvicorn/protocols/http/h11_impl.py", line 373, in run_asgi
    result = await app(self.scope, self.receive, self.send)
  File "/usr/local/lib/python3.9/site-packages/uvicorn/middleware/proxy_headers.py", line 75, in __call__
    return await self.app(scope, receive, send)
  File "/usr/local/lib/python3.9/site-packages/fastapi/applications.py", line 1054, in __call__
    await super().__call__(scope, receive, send)
  File "/usr/local/lib/python3.9/site-packages/starlette/applications.py", line 112, in __call__
    await self.middleware_stack(scope, receive, send)
  File "/usr/local/lib/python3.9/site-packages/starlette/middleware/errors.py", line 187, in __call__
    raise exc
  File "/usr/local/lib/python3.9/site-packages/starlette/middleware/errors.py", line 165, in __call__
    await self.app(scope, receive, _send)
  File "/usr/local/lib/python3.9/site-packages/starlette/middleware/cors.py", line 85, in __call__
    await self.app(scope, receive, send)
  File "/usr/local/lib/python3.9/site-packages/starlette/middleware/exceptions.py", line 62, in __call__
    await wrap_app_handling_exceptions(self.app, conn)(scope, receive, send)
  File "/usr/local/lib/python3.9/site-packages/starlette/_exception_handler.py", line 53, in wrapped_app
    raise exc
  File "/usr/local/lib/python3.9/site-packages/starlette/_exception_handler.py", line 42, in wrapped_app
    await app(scope, receive, sender)
  File "/usr/local/lib/python3.9/site-packages/starlette/routing.py", line 714, in __call__
    await self.middleware_stack(scope, receive, send)
  File "/usr/local/lib/python3.9/site-packages/starlette/routing.py", line 734, in app
    await route.handle(scope, receive, send)
  File "/usr/local/lib/python3.9/site-packages/starlette/routing.py", line 288, in handle
    await self.app(scope, receive, send)
  File "/usr/local/lib/python3.9/site-packages/starlette/routing.py", line 76, in app
    await wrap_app_handling_exceptions(app, request)(scope, receive, send)
  File "/usr/local/lib/python3.9/site-packages/starlette/_exception_handler.py", line 53, in wrapped_app
    raise exc
  File "/usr/local/lib/python3.9/site-packages/starlette/_exception_handler.py", line 42, in wrapped_app
    await app(scope, receive, sender)
  File "/usr/local/lib/python3.9/site-packages/starlette/routing.py", line 73, in app
    response = await f(request)
  File "/usr/local/lib/python3.9/site-packages/fastapi/routing.py", line 301, in app
    raw_response = await run_endpoint_function(
  File "/usr/local/lib/python3.9/site-packages/fastapi/routing.py", line 212, in run_endpoint_function
    return await dependant.call(**values)
  File "/app/main.py", line 214, in get_questions
    result = await session.execute(
  File "/usr/local/lib/python3.9/site-packages/sqlalchemy/ext/asyncio/session.py", line 463, in execute
    result = await greenlet_spawn(
  File "/usr/local/lib/python3.9/site-packages/sqlalchemy/util/_concurrency_py3k.py", line 190, in greenlet_spawn
    result = context.switch(*args, **kwargs)
  File "/usr/local/lib/python3.9/site-packages/sqlalchemy/orm/session.py", line 2365, in execute
    return self._execute_internal(
  File "/usr/local/lib/python3.9/site-packages/sqlalchemy/orm/session.py", line 2149, in _execute_internal
    statement = coercions.expect(roles.StatementRole, statement)
  File "/usr/local/lib/python3.9/site-packages/sqlalchemy/sql/coercions.py", line 395, in expect
    resolved = impl._literal_coercion(
  File "/usr/local/lib/python3.9/site-packages/sqlalchemy/sql/coercions.py", line 621, in _literal_coercion
    return self._text_coercion(element, argname, **kw)
  File "/usr/local/lib/python3.9/site-packages/sqlalchemy/sql/coercions.py", line 614, in _text_coercion
    return _no_text_coercion(element, argname)
  File "/usr/local/lib/python3.9/site-packages/sqlalchemy/sql/coercions.py", line 584, in _no_text_coercion
    raise exc_cls(
sqlalchemy.exc.ArgumentError: Textual SQL expression 'SELECT q.id, q.question_t...' should be explicitly declared as text('SELECT q.id, q.question_t...')
2025-05-06 08:29:39,510 - main - INFO - Успешная аутентификация пользователя: grigory
2025-05-06 08:29:39,510 - main - INFO - Запрос профиля пользователя: grigory
2025-05-06 08:29:45,562 - main - INFO - Успешная аутентификация пользователя: grigory
2025-05-06 08:29:45,564 - uvicorn.error - ERROR - Exception in ASGI application
Traceback (most recent call last):
  File "/usr/local/lib/python3.9/site-packages/uvicorn/protocols/http/h11_impl.py", line 373, in run_asgi
    result = await app(self.scope, self.receive, self.send)
  File "/usr/local/lib/python3.9/site-packages/uvicorn/middleware/proxy_headers.py", line 75, in __call__
    return await self.app(scope, receive, send)
  File "/usr/local/lib/python3.9/site-packages/fastapi/applications.py", line 1054, in __call__
    await super().__call__(scope, receive, send)
  File "/usr/local/lib/python3.9/site-packages/starlette/applications.py", line 112, in __call__
    await self.middleware_stack(scope, receive, send)
  File "/usr/local/lib/python3.9/site-packages/starlette/middleware/errors.py", line 187, in __call__
    raise exc
  File "/usr/local/lib/python3.9/site-packages/starlette/middleware/errors.py", line 165, in __call__
    await self.app(scope, receive, _send)
  File "/usr/local/lib/python3.9/site-packages/starlette/middleware/cors.py", line 85, in __call__
    await self.app(scope, receive, send)
  File "/usr/local/lib/python3.9/site-packages/starlette/middleware/exceptions.py", line 62, in __call__
    await wrap_app_handling_exceptions(self.app, conn)(scope, receive, send)
  File "/usr/local/lib/python3.9/site-packages/starlette/_exception_handler.py", line 53, in wrapped_app
    raise exc
  File "/usr/local/lib/python3.9/site-packages/starlette/_exception_handler.py", line 42, in wrapped_app
    await app(scope, receive, sender)
  File "/usr/local/lib/python3.9/site-packages/starlette/routing.py", line 714, in __call__
    await self.middleware_stack(scope, receive, send)
  File "/usr/local/lib/python3.9/site-packages/starlette/routing.py", line 734, in app
    await route.handle(scope, receive, send)
  File "/usr/local/lib/python3.9/site-packages/starlette/routing.py", line 288, in handle
    await self.app(scope, receive, send)
  File "/usr/local/lib/python3.9/site-packages/starlette/routing.py", line 76, in app
    await wrap_app_handling_exceptions(app, request)(scope, receive, send)
  File "/usr/local/lib/python3.9/site-packages/starlette/_exception_handler.py", line 53, in wrapped_app
    raise exc
  File "/usr/local/lib/python3.9/site-packages/starlette/_exception_handler.py", line 42, in wrapped_app
    await app(scope, receive, sender)
  File "/usr/local/lib/python3.9/site-packages/starlette/routing.py", line 73, in app
    response = await f(request)
  File "/usr/local/lib/python3.9/site-packages/fastapi/routing.py", line 301, in app
    raw_response = await run_endpoint_function(
  File "/usr/local/lib/python3.9/site-packages/fastapi/routing.py", line 212, in run_endpoint_function
    return await dependant.call(**values)
  File "/app/main.py", line 214, in get_questions
    result = await session.execute(
  File "/usr/local/lib/python3.9/site-packages/sqlalchemy/ext/asyncio/session.py", line 463, in execute
    result = await greenlet_spawn(
  File "/usr/local/lib/python3.9/site-packages/sqlalchemy/util/_concurrency_py3k.py", line 190, in greenlet_spawn
    result = context.switch(*args, **kwargs)
  File "/usr/local/lib/python3.9/site-packages/sqlalchemy/orm/session.py", line 2365, in execute
    return self._execute_internal(
  File "/usr/local/lib/python3.9/site-packages/sqlalchemy/orm/session.py", line 2149, in _execute_internal
    statement = coercions.expect(roles.StatementRole, statement)
  File "/usr/local/lib/python3.9/site-packages/sqlalchemy/sql/coercions.py", line 395, in expect
    resolved = impl._literal_coercion(
  File "/usr/local/lib/python3.9/site-packages/sqlalchemy/sql/coercions.py", line 621, in _literal_coercion
    return self._text_coercion(element, argname, **kw)
  File "/usr/local/lib/python3.9/site-packages/sqlalchemy/sql/coercions.py", line 614, in _text_coercion
    return _no_text_coercion(element, argname)
  File "/usr/local/lib/python3.9/site-packages/sqlalchemy/sql/coercions.py", line 584, in _no_text_coercion
    raise exc_cls(
sqlalchemy.exc.ArgumentError: Textual SQL expression 'SELECT q.id, q.question_t...' should be explicitly declared as text('SELECT q.id, q.question_t...')
2025-05-06 08:29:58,091 - main - INFO - Успешная аутентификация пользователя: grigory
2025-05-06 08:29:58,092 - main - INFO - Запрос профиля пользователя: grigory
2025-05-06 08:29:58,812 - main - INFO - Успешная аутентификация пользователя: grigory
2025-05-06 08:29:58,812 - main - INFO - Запрос профиля пользователя: grigory
2025-05-06 08:30:00,675 - main - INFO - Успешная аутентификация пользователя: grigory
2025-05-06 08:30:00,676 - main - INFO - Запрос профиля пользователя: grigory
2025-05-06 08:30:01,596 - main - INFO - Успешная аутентификация пользователя: grigory
2025-05-06 08:30:01,596 - main - INFO - Запрос профиля пользователя: grigory
2025-05-06 08:30:03,425 - main - INFO - Успешная аутентификация пользователя: grigory
2025-05-06 08:30:03,425 - main - INFO - Запрос профиля пользователя: grigory
2025-05-06 08:30:10,346 - main - INFO - Успешная аутентификация пользователя: grigory
2025-05-06 08:30:50,220 - main - INFO - Успешная аутентификация пользователя: grigory
2025-05-06 08:30:50,220 - main - INFO - Запрос профиля пользователя: grigory
2025-05-06 08:30:52,766 - main - INFO - Успешная аутентификация пользователя: grigory
2025-05-06 08:30:52,766 - main - INFO - Запрос профиля пользователя: grigory
2025-05-06 08:32:08,406 - main - INFO - Успешная аутентификация пользователя: grigory
2025-05-06 08:32:08,409 - uvicorn.error - ERROR - Exception in ASGI application
Traceback (most recent call last):
  File "/usr/local/lib/python3.9/site-packages/uvicorn/protocols/http/h11_impl.py", line 373, in run_asgi
    result = await app(self.scope, self.receive, self.send)
  File "/usr/local/lib/python3.9/site-packages/uvicorn/middleware/proxy_headers.py", line 75, in __call__
    return await self.app(scope, receive, send)
  File "/usr/local/lib/python3.9/site-packages/fastapi/applications.py", line 1054, in __call__
    await super().__call__(scope, receive, send)
  File "/usr/local/lib/python3.9/site-packages/starlette/applications.py", line 112, in __call__
    await self.middleware_stack(scope, receive, send)
  File "/usr/local/lib/python3.9/site-packages/starlette/middleware/errors.py", line 187, in __call__
    raise exc
  File "/usr/local/lib/python3.9/site-packages/starlette/middleware/errors.py", line 165, in __call__
    await self.app(scope, receive, _send)
  File "/usr/local/lib/python3.9/site-packages/starlette/middleware/cors.py", line 85, in __call__
    await self.app(scope, receive, send)
  File "/usr/local/lib/python3.9/site-packages/starlette/middleware/exceptions.py", line 62, in __call__
    await wrap_app_handling_exceptions(self.app, conn)(scope, receive, send)
  File "/usr/local/lib/python3.9/site-packages/starlette/_exception_handler.py", line 53, in wrapped_app
    raise exc
  File "/usr/local/lib/python3.9/site-packages/starlette/_exception_handler.py", line 42, in wrapped_app
    await app(scope, receive, sender)
  File "/usr/local/lib/python3.9/site-packages/starlette/routing.py", line 714, in __call__
    await self.middleware_stack(scope, receive, send)
  File "/usr/local/lib/python3.9/site-packages/starlette/routing.py", line 734, in app
    await route.handle(scope, receive, send)
  File "/usr/local/lib/python3.9/site-packages/starlette/routing.py", line 288, in handle
    await self.app(scope, receive, send)
  File "/usr/local/lib/python3.9/site-packages/starlette/routing.py", line 76, in app
    await wrap_app_handling_exceptions(app, request)(scope, receive, send)
  File "/usr/local/lib/python3.9/site-packages/starlette/_exception_handler.py", line 53, in wrapped_app
    raise exc
  File "/usr/local/lib/python3.9/site-packages/starlette/_exception_handler.py", line 42, in wrapped_app
    await app(scope, receive, sender)
  File "/usr/local/lib/python3.9/site-packages/starlette/routing.py", line 73, in app
    response = await f(request)
  File "/usr/local/lib/python3.9/site-packages/fastapi/routing.py", line 301, in app
    raw_response = await run_endpoint_function(
  File "/usr/local/lib/python3.9/site-packages/fastapi/routing.py", line 212, in run_endpoint_function
    return await dependant.call(**values)
  File "/app/main.py", line 214, in get_questions
    result = await session.execute(
  File "/usr/local/lib/python3.9/site-packages/sqlalchemy/ext/asyncio/session.py", line 463, in execute
    result = await greenlet_spawn(
  File "/usr/local/lib/python3.9/site-packages/sqlalchemy/util/_concurrency_py3k.py", line 190, in greenlet_spawn
    result = context.switch(*args, **kwargs)
  File "/usr/local/lib/python3.9/site-packages/sqlalchemy/orm/session.py", line 2365, in execute
    return self._execute_internal(
  File "/usr/local/lib/python3.9/site-packages/sqlalchemy/orm/session.py", line 2149, in _execute_internal
    statement = coercions.expect(roles.StatementRole, statement)
  File "/usr/local/lib/python3.9/site-packages/sqlalchemy/sql/coercions.py", line 395, in expect
    resolved = impl._literal_coercion(
  File "/usr/local/lib/python3.9/site-packages/sqlalchemy/sql/coercions.py", line 621, in _literal_coercion
    return self._text_coercion(element, argname, **kw)
  File "/usr/local/lib/python3.9/site-packages/sqlalchemy/sql/coercions.py", line 614, in _text_coercion
    return _no_text_coercion(element, argname)
  File "/usr/local/lib/python3.9/site-packages/sqlalchemy/sql/coercions.py", line 584, in _no_text_coercion
    raise exc_cls(
sqlalchemy.exc.ArgumentError: Textual SQL expression 'SELECT q.id, q.question_t...' should be explicitly declared as text('SELECT q.id, q.question_t...')
